from exception_demo import my_function

try:
    my_function()
finally:
    print("The final line")
